Workbook

Sheet Dashboard
A1: E-COMMERCE SALES & CUSTOMER ANALYTICS
A3: Synthetic 2025 order dataset | Currency: INR
A4: Region Filter | B4: All | D4: Select a region to update KPI cards.
A6: DELIVERED REVENUE | D6: ESTIMATED PROFIT | G6: DELIVERED ORDERS | J6: PROFIT MARGIN
A7: =IF($B$4="All",SUMIFS(Clean_Data!$O$2:$O$501,Clean_Data!$N$2:$N$501,"Delivered"),SUMIFS(Clean_Data!$O$2:$O$501,Clean_Data!$D$2:$D$501,$B$4,Clean_Data!$N$2:$N$501,"Delivered")) | D7: =IF($B$4="All",SUMIFS(Clean_Data!$P$2:$P$501,Clean_Data!$N$2:$N$501,"Delivered"),SUMIFS(Clean_Data!$P$2:$P$501,Clean_Data!$D$2:$D$501,$B$4,Clean_Data!$N$2:$N$501,"Delivered")) | G7: =IF($B$4="All",COUNTIF(Clean_Data!$N$2:$N$501,"Delivered"),COUNTIFS(Clean_Data!$D$2:$D$501,$B$4,Clean_Data!$N$2:$N$501,"Delivered")) | J7: =IFERROR(IF($B$4="All",SUMIFS(Clean_Data!$P$2:$P$501,Clean_Data!$N$2:$N$501,"Delivered")/SUMIFS(Clean_Data!$O$2:$O$501,Clean_Data!$N$2:$N$501,"Delivered"),SUMIFS(Clean_Data!$P$2:$P$501,Clean_Data!$D$2:$D$501,$B$4,Clean_Data!$N$2:$N$501,"Delivered")/SUMIFS(Clean_Data!$O$2:$O$501,Clean_Data!$D$2:$D$501,$B$4,Clean_Data!$N$2:$N$501,"Delivered")),0)
A42: KPI cards respond to the region selector; charts show overall dataset summaries.

Sheet Raw_Data
A1: Order_ID | B1: Order_Date | C1: Customer_ID | D1: Region | E1: City | F1: Sales_Channel | G1: Category | H1: Product | I1: Quantity | J1: Unit_Price_INR | K1: Discount_Rate | L1: Estimated_Cost_INR | M1: Payment_Method | N1: Order_Status
A2: ORD-00001 | B2: 2025-09-04 | C2: CUST-0163 | D2: South | E2: Chennai | F2: Marketplace | G2: Beauty | H2: Face Wash | I2: 4 | J2: 1155 | K2: 0.02 | L2: 1940.4 | M2: Net Banking | N2: Delivered
A3: ORD-00002 | B3: 2025-07-06 | C3: CUST-0006 | D3: East | E3: Bhubaneswar | F3: Social Media | G3: Home & Kitchen | H3: Water Bottle | I3: 2 | J3: 602.09 | K3: 0.08 | L3: 626.17 | M3: Cash on Delivery | N3: Delivered
A4: ORD-00003 | B4: 2025-03-12 | C4: CUST-0037 | D4: East | E4: Kolkata | F4: Marketplace | G4: Beauty | H4: Face Wash | I4: 4 | J4: 1951.88 | K4: 0.08 | L4: 3279.16 | M4: Debit Card | N4: Delivered
A5: ORD-00004 | B5: 2025-12-20 | C5: CUST-0017 | D5: South | E5: Bengaluru | F5: Retail Store | G5: Home & Kitchen | H5: Bedsheet | I5: 5 | J5: 2937.26 | K5: 0.15 | L5: 7636.88 | M5: Cash on Delivery | N5: Delivered
A6: ORD-00005 | B6: 2025-04-02 | C6: CUST-0073 | D6: Central | E6: Indore | F6: Mobile App | G6: Beauty | H6: Moisturizer | I6: 1 | J6: 1229.54 | K6: 0.1 | L6: 516.41 | M6: Cash on Delivery | N6: Delivered
A7: ORD-00006 | B7: 2025-06-02 | C7: CUST-0059 | D7: South | E7: Bengaluru | F7: Mobile App | G7: Home & Kitchen | H7: Water Bottle | I7: 4 | J7: 4425.52 | K7: 0.02 | L7: 9205.08 | M7: Cash on Delivery | N7: Delivered
A8: ORD-00007 | B8: 2025-09-06 | C8: CUST-0145 | D8: West | E8: Surat | F8: Website | G8: Books | H8: Business Book | I8: 1 | J8: 168.35 | K8: 0.15 | L8: 75.76 | M8: Debit Card | N8: Delivered
A9: ORD-00008 | B9: 2025-02-17 | C9: CUST-0156 | D9: East | E9: Kolkata | F9: Retail Store | G9: Home & Kitchen | H9: Desk Lamp | I9: 1 | J9: 3419.76 | K9: 0.15 | L9: 1778.28 | M9: UPI | N9: Delivered
A10: ORD-00009 | B10: 2025-09-05 | C10: CUST-0090 | D10: East | E10: Guwahati | F10: Marketplace | G10: Beauty | H10: Hair Serum | I10: 2 | J10: 1591.06 | K10: 0.02 | L10: 1336.49 | M10: Debit Card | N10: Delivered
A11: ORD-00010 | B11: 2025-06-21 | C11: CUST-0106 | D11: East | E11: Kolkata | F11: Mobile App | G11: Fashion | H11: Sneakers | I11: 2 | J11: 1792.86 | K11: 0.05 | L11: 1721.15 | M11: UPI | N11: Delivered
A12: ORD-00011 | B12: 2025-11-05 | C12: CUST-0154 | D12: North | E12: Dehradun | F12: Retail Store | G12: Books | H12: Exam Guide | I12: 1 | J12: 151.48 | K12: 0 | L12: 68.17 | M12: Credit Card | N12: Delivered
A13: ORD-00012 | B13: 2025-05-31 | C13: CUST-0084 | D13: South | E13: Chennai | F13: Website | G13: Electronics | H13: Power Bank | I13: 1 | J13: 15289.56 | K13: 0.1 | L13: 11008.48 | M13: Cash on Delivery | N13: Delivered
... A44: ORD-00043 | B44: 2025-05-08 | C44: CUST-0007 | D44: South | E44: Hyderabad | F44: Mobile App | G44: Beauty | H44: Lip Balm | I44: 1 | J44: 1537 | K44: 0.1 | L44: 645.54 | M44: Cash on Delivery | N44: Cancelled
A45: ORD-00044 | B45: 2025-02-01 | C45: CUST-0085 | D45: South | E45: Hyderabad | G45: Electronics | H45: Smartwatch | I45: 1 | J45: 8344.42 | K45: 0.05 | L45: 6007.98 | M45: Cash on Delivery | N45: Delivered
A46: ORD-00045 | B46: 2025-07-02 | C46: CUST-0138 | D46: South | E46: Chennai | F46: Marketplace | G46: Beauty | H46: Moisturizer | I46: 2 | J46: 205 | K46: 0 | L46: 172.2 | M46: Cash on Delivery | N46: Delivered
A47: ORD-00046 | B47: 2025-03-21 | C47: CUST-0085 | D47: South | E47: Bengaluru | F47: Marketplace | G47: Books | H47: Notebook Set | I47: 5 | J47: 965.1 | K47: 0.08 | L47: 2171.47 | M47: Cash on Delivery | N47: Cancelled
A48: ORD-00047 | B48: 2025-11-30 | C48: CUST-0098 | D48: South | E48: Hyderabad | F48: Marketplace | G48: Home & Kitchen | H48: Storage Box | I48: 2 | J48: 1657.79 | K48: 0.08 | L48: 1724.1 | M48: Net Banking | N48: Delivered
A49: ORD-00048 | B49: 2025-12-15 | C49: CUST-0157 | D49: Central | E49: Indore | F49: Social Media | G49: Electronics | H49: Smartwatch | I49: 2 | J49: 13761.6 | K49: 0.05 | L49: 19816.7 | M49: UPI | N49: Delivered
A50: ORD-00049 | B50: 2025-06-21 | C50: CUST-0113 | D50: East | E50: Kolkata | F50: Marketplace | G50: Fashion | H50: Jeans | I50: 1 | J50: 5394.85 | K50: 0 | L50: 2589.53 | M50: Credit Card | N50: Delivered
A51: ORD-00050 | B51: 2025-04-02 | C51: CUST-0166 | D51: South | E51: Bengaluru | F51: Website | G51: Beauty | H51: Lip Balm | I51: 2 | J51: 1825.03 | K51: 0.05 | L51: 1533.03 | M51: Net Banking | N51: Delivered
A52: ORD-00051 | B52: 2025-10-21 | C52: CUST-0061 | D52: West | E52: Pune | F52: Retail Store | G52: Books | H52: Exam Guide | I52: 1 | J52: 559.74 | K52: 0 | L52: 251.88 | M52: Net Banking | N52: Delivered
A53: ORD-00052 | B53: 2025-04-06 | C53: CUST-0119 | D53: East | E53: Bhubaneswar | F53: Mobile App | G53: Home & Kitchen | H53: Water Bottle | I53: 1 | J53: 3297.84 | K53: 0 | L53: 1714.88 | M53: UPI | N53: Delivered
A54: ORD-00053 | B54: 2025-02-06 | C54: CUST-0176 | D54: Central | E54: Bhopal | F54: Mobile App | G54: Books | H54: Notebook Set | I54: 1 | J54: 941.9 | K54: 0.05 | L54: 423.86 | M54: Credit Card | N54: Delivered
A55: ORD-00054 | B55: 2025-08-31 | C55: CUST-0178 | D55: East | E55: Kolkata | F55: Mobile App | G55: Books | H55: Notebook Set | I55: 3 | J55: 508.4 | K55: 0.02 | L55: 686.34 | M55: UPI | N55: Delivered
A56: ORD-00055 | B56: 2025-04-02 | C56: CUST-0058 | D56: East | E56: Patna | F56: Marketplace | G56: Beauty | H56: Face Wash | I56: 5 | J56: 512.14 | K56: 0.02 | L56: 1075.49 | M56: UPI | N56: Cancelled
A57: ORD-00056 | B57: 2025-08-06 | C57: CUST-0112 | D57: North | E57: Chandigarh | F57: Social Media | G57: Home & Kitchen | H57: Storage Box | I57: 3 | J57: 2969.96 | K57: 0.15 | L57: 4633.14 | M57: Cash on Delivery | N57: Delivered
... A247: ORD-00246 | B247: 2025-07-11 | C247: CUST-0049 | D247: North | E247: Dehradun | F247: Website | G247: Fashion | H247: Sneakers | I247: 2 | J247: 992.88 | K247: 0.05 | L247: 953.16 | M247: Net Banking | N247: Delivered
A248: ORD-00247 | B248: 2025-09-28 | C248: CUST-0058 | D248: Central | E248: Nagpur | G248: Books | H248: Notebook Set | I248: 3 | J248: 1537.25 | K248: 0.1 | L248: 2075.29 | M248: Credit Card | N248: Delivered
A249: ORD-00248 | B249: 2025-07-06 | C249: CUST-0165 | D249: Central | E249: Indore | F249: Marketplace | G249: Books | H249: Programming Book | I249: 4 | J249: 1720.65 | K249: 0.05 | L249: 3097.17 | M249: Net Banking | N249: Delivered
A250: ORD-00249 | B250: 2025-07-03 | C250: CUST-0052 | D250: South | E250: Kochi | F250: Social Media | G250: Home & Kitchen | H250: Storage Box | I250: 5 | J250: 3572.43 | K250: 0.05 | L250: 9288.32 | M250: Net Banking | N250: Delivered
A251: ORD-00250 | B251: 2025-12-16 | C251: CUST-0130 | D251: Central | E251: Nagpur | F251: Social Media | G251: Beauty | H251: Lip Balm | I251: 5 | J251: 1677.69 | K251: 0.08 | L251: 3523.15 | M251: Credit Card | N251: Cancelled
A252: ORD-00251 | B252: 2025-07-17 | C252: CUST-0083 | D252: East | E252: Patna | F252: Marketplace | G252: Electronics | H252: Bluetooth Speaker | I252: 5 | J252: 14231.09 | K252: 0.08 | L252: 51231.92 | M252: Cash on Delivery | N252: Delivered
A253: ORD-00252 | B253: 2025-05-30 | C253: CUST-0048 | D253: West | E253: Surat | F253: Mobile App | G253: Fashion | H253: Hoodie | I253: 4 | J253: 5829.6 | K253: 0.1 | L253: 11192.83 | M253: Debit Card | N253: Delivered
A254: ORD-00253 | B254: 2025-06-12 | C254: CUST-0030 | D254: Central | E254: Bhopal | F254: Marketplace | G254: Home & Kitchen | H254: Cookware Set | I254: 5 | J254: 2353.33 | K254: 0.02 | L254: 6118.66 | M254: Credit Card | N254: Delivered
A255: ORD-00254 | B255: 2025-03-05 | C255: CUST-0015 | D255: North | E255: Jaipur | F255: Mobile App | G255: Fashion | H255: Backpack | I255: 4 | J255: 6450.54 | K255: 0.15 | L255: 12385.04 | M255: Debit Card | N255: Delivered
A256: ORD-00255 | B256: 2025-05-13 | C256: CUST-0025 | D256: East | E256: Guwahati | F256: Retail Store | G256: Books | H256: Programming Book | I256: 3 | J256: 573.81 | K256: 0.05 | L256: 774.64 | M256: Cash on Delivery | N256: Delivered
A257: ORD-00256 | B257: 2025-09-15 | C257: CUST-0171 | D257: North | E257: Chandigarh | F257: Social Media | G257: Books | H257: Fiction Novel | I257: 2 | J257: 558.99 | K257: 0.05 | L257: 503.09 | M257: Cash on Delivery | N257: Delivered
A258: ORD-00257 | B258: 2025-10-10 | C258: CUST-0169 | D258: Central | E258: Bhopal | F258: Marketplace | G258: Electronics | H258: USB-C Hub | I258: 3 | J258: 4738.29 | K258: 0.1 | L258: 10234.71 | M258: UPI | N258: Delivered
A259: ORD-00258 | B259: 2025-01-14 | C259: CUST-0071 | D259: Central | E259: Indore | F259: Website | G259: Home & Kitchen | H259: Desk Lamp | I259: 1 | J259: 281.36 | K259: 0.08 | L259: 146.31 | M259: UPI | N259: Delivered
...

Sheet Clean_Data
A1: Order_ID | B1: Order_Date | C1: Customer_ID | D1: Region | E1: City | F1: Sales_Channel | G1: Category | H1: Product | I1: Quantity | J1: Unit_Price_INR | K1: Discount_Rate | L1: Estimated_Cost_INR | M1: Payment_Method | N1: Order_Status | O1: Revenue_INR | P1: Estimated_Profit_INR | Q1: Order_Month | R1: Order_Outcome
A2: ORD-00001 | B2: 45904 | C2: CUST-0163 | D2: South | E2: Chennai | F2: Marketplace | G2: Beauty | H2: Face Wash | I2: 4 | J2: 1155 | K2: 0.02 | L2: 1940.4 | M2: Net Banking | N2: Delivered | O2: 4527.6 | P2: 2587.2 | Q2: Sep-2025 | R2: Completed
A3: ORD-00002 | B3: 45844 | C3: CUST-0006 | D3: East | E3: Bhubaneswar | F3: Social Media | G3: Home & Kitchen | H3: Water Bottle | I3: 2 | J3: 602.09 | K3: 0.08 | L3: 626.17 | M3: Cash on Delivery | N3: Delivered | O3: 1107.85 | P3: 481.68 | Q3: Jul-2025 | R3: Completed
A4: ORD-00003 | B4: 45728 | C4: CUST-0037 | D4: East | E4: Kolkata | F4: Marketplace | G4: Beauty | H4: Face Wash | I4: 4 | J4: 1951.88 | K4: 0.08 | L4: 3279.16 | M4: Debit Card | N4: Delivered | O4: 7182.92 | P4: 3903.76 | Q4: Mar-2025 | R4: Completed
A5: ORD-00004 | B5: 46011 | C5: CUST-0017 | D5: South | E5: Bengaluru | F5: Retail Store | G5: Home & Kitchen | H5: Bedsheet | I5: 5 | J5: 2937.26 | K5: 0.15 | L5: 7636.88 | M5: Cash on Delivery | N5: Delivered | O5: 12483.36 | P5: 4846.48 | Q5: Dec-2025 | R5: Completed
A6: ORD-00005 | B6: 45749 | C6: CUST-0073 | D6: Central | E6: Indore | F6: Mobile App | G6: Beauty | H6: Moisturizer | I6: 1 | J6: 1229.54 | K6: 0.1 | L6: 516.41 | M6: Cash on Delivery | N6: Delivered | O6: 1106.59 | P6: 590.18 | Q6: Apr-2025 | R6: Completed
A7: ORD-00006 | B7: 45810 | C7: CUST-0059 | D7: South | E7: Bengaluru | F7: Mobile App | G7: Home & Kitchen | H7: Water Bottle | I7: 4 | J7: 4425.52 | K7: 0.02 | L7: 9205.08 | M7: Cash on Delivery | N7: Delivered | O7: 17348.04 | P7: 8142.96 | Q7: Jun-2025 | R7: Completed
A8: ORD-00007 | B8: 45906 | C8: CUST-0145 | D8: West | E8: Surat | F8: Website | G8: Books | H8: Business Book | I8: 1 | J8: 168.35 | K8: 0.15 | L8: 75.76 | M8: Debit Card | N8: Delivered | O8: 143.1 | P8: 67.34 | Q8: Sep-2025 | R8: Completed
A9: ORD-00008 | B9: 45705 | C9: CUST-0156 | D9: East | E9: Kolkata | F9: Retail Store | G9: Home & Kitchen | H9: Desk Lamp | I9: 1 | J9: 3419.76 | K9: 0.15 | L9: 1778.28 | M9: UPI | N9: Delivered | O9: 2906.8 | P9: 1128.52 | Q9: Feb-2025 | R9: Completed
A10: ORD-00009 | B10: 45905 | C10: CUST-0090 | D10: East | E10: Guwahati | F10: Marketplace | G10: Beauty | H10: Hair Serum | I10: 2 | J10: 1591.06 | K10: 0.02 | L10: 1336.49 | M10: Debit Card | N10: Delivered | O10: 3118.48 | P10: 1781.99 | Q10: Sep-2025 | R10: Completed
A11: ORD-00010 | B11: 45829 | C11: CUST-0106 | D11: East | E11: Kolkata | F11: Mobile App | G11: Fashion | H11: Sneakers | I11: 2 | J11: 1792.86 | K11: 0.05 | L11: 1721.15 | M11: UPI | N11: Delivered | O11: 3406.43 | P11: 1685.28 | Q11: Jun-2025 | R11: Completed
A12: ORD-00011 | B12: 45966 | C12: CUST-0154 | D12: North | E12: Dehradun | F12: Retail Store | G12: Books | H12: Exam Guide | I12: 1 | J12: 151.48 | K12: 0 | L12: 68.17 | M12: Credit Card | N12: Delivered | O12: 151.48 | P12: 83.31 | Q12: Nov-2025 | R12: Completed
A13: ORD-00012 | B13: 45808 | C13: CUST-0084 | D13: South | E13: Chennai | F13: Website | G13: Electronics | H13: Power Bank | I13: 1 | J13: 15289.56 | K13: 0.1 | L13: 11008.48 | M13: Cash on Delivery | N13: Delivered | O13: 13760.6 | P13: 2752.12 | Q13: May-2025 | R13: Completed
... A501: ORD-00500 | B501: 45913 | C501: CUST-0180 | D501: North | E501: Jaipur | F501: Marketplace | G501: Books | H501: Programming Book | I501: 5 | J501: 1692.26 | K501: 0.05 | L501: 3807.58 | M501: Credit Card | N501: Delivered | O501: 8038.23 | P501: 4230.65 | Q501: Sep-2025 | R501: Completed

Sheet Analysis
A1: E-COMMERCE ANALYTICS | SUMMARY TABLES
A3: Month | B3: Revenue (INR) | C3: Estimated Profit (INR) | E3: Category | F3: Revenue (INR) | G3: Orders
A4: 45658 | B4: =SUMIFS(Clean_Data!$O$2:$O$501,Clean_Data!$B$2:$B$501,">="&A4,Clean_Data!$B$2:$B$501,"<"&EDATE(A4,1),Clean_Data!$N$2:$N$501,"Delivered") | C4: =SUMIFS(Clean_Data!$P$2:$P$501,Clean_Data!$B$2:$B$501,">="&A4,Clean_Data!$B$2:$B$501,"<"&EDATE(A4,1),Clean_Data!$N$2:$N$501,"Delivered") | E4: Electronics | F4: =SUMIFS(Clean_Data!$O$2:$O$501,Clean_Data!$G$2:$G$501,E4,Clean_Data!$N$2:$N$501,"Delivered") | G4: =COUNTIFS(Clean_Data!$G$2:$G$501,E4,Clean_Data!$N$2:$N$501,"Delivered")
A5: 45689 | B5: =SUMIFS(Clean_Data!$O$2:$O$501,Clean_Data!$B$2:$B$501,">="&A5,Clean_Data!$B$2:$B$501,"<"&EDATE(A5,1),Clean_Data!$N$2:$N$501,"Delivered") | C5: =SUMIFS(Clean_Data!$P$2:$P$501,Clean_Data!$B$2:$B$501,">="&A5,Clean_Data!$B$2:$B$501,"<"&EDATE(A5,1),Clean_Data!$N$2:$N$501,"Delivered") | E5: Fashion | F5: =SUMIFS(Clean_Data!$O$2:$O$501,Clean_Data!$G$2:$G$501,E5,Clean_Data!$N$2:$N$501,"Delivered") | G5: =COUNTIFS(Clean_Data!$G$2:$G$501,E5,Clean_Data!$N$2:$N$501,"Delivered")
A6: 45717 | B6: =SUMIFS(Clean_Data!$O$2:$O$501,Clean_Data!$B$2:$B$501,">="&A6,Clean_Data!$B$2:$B$501,"<"&EDATE(A6,1),Clean_Data!$N$2:$N$501,"Delivered") | C6: =SUMIFS(Clean_Data!$P$2:$P$501,Clean_Data!$B$2:$B$501,">="&A6,Clean_Data!$B$2:$B$501,"<"&EDATE(A6,1),Clean_Data!$N$2:$N$501,"Delivered") | E6: Home & Kitchen | F6: =SUMIFS(Clean_Data!$O$2:$O$501,Clean_Data!$G$2:$G$501,E6,Clean_Data!$N$2:$N$501,"Delivered") | G6: =COUNTIFS(Clean_Data!$G$2:$G$501,E6,Clean_Data!$N$2:$N$501,"Delivered")
A7: 45748 | B7: =SUMIFS(Clean_Data!$O$2:$O$501,Clean_Data!$B$2:$B$501,">="&A7,Clean_Data!$B$2:$B$501,"<"&EDATE(A7,1),Clean_Data!$N$2:$N$501,"Delivered") | C7: =SUMIFS(Clean_Data!$P$2:$P$501,Clean_Data!$B$2:$B$501,">="&A7,Clean_Data!$B$2:$B$501,"<"&EDATE(A7,1),Clean_Data!$N$2:$N$501,"Delivered") | E7: Beauty | F7: =SUMIFS(Clean_Data!$O$2:$O$501,Clean_Data!$G$2:$G$501,E7,Clean_Data!$N$2:$N$501,"Delivered") | G7: =COUNTIFS(Clean_Data!$G$2:$G$501,E7,Clean_Data!$N$2:$N$501,"Delivered")
A8: 45778 | B8: =SUMIFS(Clean_Data!$O$2:$O$501,Clean_Data!$B$2:$B$501,">="&A8,Clean_Data!$B$2:$B$501,"<"&EDATE(A8,1),Clean_Data!$N$2:$N$501,"Delivered") | C8: =SUMIFS(Clean_Data!$P$2:$P$501,Clean_Data!$B$2:$B$501,">="&A8,Clean_Data!$B$2:$B$501,"<"&EDATE(A8,1),Clean_Data!$N$2:$N$501,"Delivered") | E8: Books | F8: =SUMIFS(Clean_Data!$O$2:$O$501,Clean_Data!$G$2:$G$501,E8,Clean_Data!$N$2:$N$501,"Delivered") | G8: =COUNTIFS(Clean_Data!$G$2:$G$501,E8,Clean_Data!$N$2:$N$501,"Delivered")
A9: 45809 | B9: =SUMIFS(Clean_Data!$O$2:$O$501,Clean_Data!$B$2:$B$501,">="&A9,Clean_Data!$B$2:$B$501,"<"&EDATE(A9,1),Clean_Data!$N$2:$N$501,"Delivered") | C9: =SUMIFS(Clean_Data!$P$2:$P$501,Clean_Data!$B$2:$B$501,">="&A9,Clean_Data!$B$2:$B$501,"<"&EDATE(A9,1),Clean_Data!$N$2:$N$501,"Delivered")
A10: 45839 | B10: =SUMIFS(Clean_Data!$O$2:$O$501,Clean_Data!$B$2:$B$501,">="&A10,Clean_Data!$B$2:$B$501,"<"&EDATE(A10,1),Clean_Data!$N$2:$N$501,"Delivered") | C10: =SUMIFS(Clean_Data!$P$2:$P$501,Clean_Data!$B$2:$B$501,">="&A10,Clean_Data!$B$2:$B$501,"<"&EDATE(A10,1),Clean_Data!$N$2:$N$501,"Delivered")
A11: 45870 | B11: =SUMIFS(Clean_Data!$O$2:$O$501,Clean_Data!$B$2:$B$501,">="&A11,Clean_Data!$B$2:$B$501,"<"&EDATE(A11,1),Clean_Data!$N$2:$N$501,"Delivered") | C11: =SUMIFS(Clean_Data!$P$2:$P$501,Clean_Data!$B$2:$B$501,">="&A11,Clean_Data!$B$2:$B$501,"<"&EDATE(A11,1),Clean_Data!$N$2:$N$501,"Delivered")
A12: 45901 | B12: =SUMIFS(Clean_Data!$O$2:$O$501,Clean_Data!$B$2:$B$501,">="&A12,Clean_Data!$B$2:$B$501,"<"&EDATE(A12,1),Clean_Data!$N$2:$N$501,"Delivered") | C12: =SUMIFS(Clean_Data!$P$2:$P$501,Clean_Data!$B$2:$B$501,">="&A12,Clean_Data!$B$2:$B$501,"<"&EDATE(A12,1),Clean_Data!$N$2:$N$501,"Delivered")
A13: 45931 | B13: =SUMIFS(Clean_Data!$O$2:$O$501,Clean_Data!$B$2:$B$501,">="&A13,Clean_Data!$B$2:$B$501,"<"&EDATE(A13,1),Clean_Data!$N$2:$N$501,"Delivered") | C13: =SUMIFS(Clean_Data!$P$2:$P$501,Clean_Data!$B$2:$B$501,">="&A13,Clean_Data!$B$2:$B$501,"<"&EDATE(A13,1),Clean_Data!$N$2:$N$501,"Delivered")
A14: 45962 | B14: =SUMIFS(Clean_Data!$O$2:$O$501,Clean_Data!$B$2:$B$501,">="&A14,Clean_Data!$B$2:$B$501,"<"&EDATE(A14,1),Clean_Data!$N$2:$N$501,"Delivered") | C14: =SUMIFS(Clean_Data!$P$2:$P$501,Clean_Data!$B$2:$B$501,">="&A14,Clean_Data!$B$2:$B$501,"<"&EDATE(A14,1),Clean_Data!$N$2:$N$501,"Delivered")
A15: 45992 | B15: =SUMIFS(Clean_Data!$O$2:$O$501,Clean_Data!$B$2:$B$501,">="&A15,Clean_Data!$B$2:$B$501,"<"&EDATE(A15,1),Clean_Data!$N$2:$N$501,"Delivered") | C15: =SUMIFS(Clean_Data!$P$2:$P$501,Clean_Data!$B$2:$B$501,">="&A15,Clean_Data!$B$2:$B$501,"<"&EDATE(A15,1),Clean_Data!$N$2:$N$501,"Delivered")
A19: Sales Channel | B19: Revenue (INR) | D19: Order Status | E19: Order Count | G19: Region | H19: Revenue (INR)
A20: Website | B20: =SUMIFS(Clean_Data!$O$2:$O$501,Clean_Data!$F$2:$F$501,A20,Clean_Data!$N$2:$N$501,"Delivered") | D20: Delivered | E20: =COUNTIF(Clean_Data!$N$2:$N$501,D20) | G20: North | H20: =SUMIFS(Clean_Data!$O$2:$O$501,Clean_Data!$D$2:$D$501,G20,Clean_Data!$N$2:$N$501,"Delivered")
A21: Mobile App | B21: =SUMIFS(Clean_Data!$O$2:$O$501,Clean_Data!$F$2:$F$501,A21,Clean_Data!$N$2:$N$501,"Delivered") | D21: Cancelled | E21: =COUNTIF(Clean_Data!$N$2:$N$501,D21) | G21: South | H21: =SUMIFS(Clean_Data!$O$2:$O$501,Clean_Data!$D$2:$D$501,G21,Clean_Data!$N$2:$N$501,"Delivered")
A22: Marketplace | B22: =SUMIFS(Clean_Data!$O$2:$O$501,Clean_Data!$F$2:$F$501,A22,Clean_Data!$N$2:$N$501,"Delivered") | D22: Returned | E22: =COUNTIF(Clean_Data!$N$2:$N$501,D22) | G22: East | H22: =SUMIFS(Clean_Data!$O$2:$O$501,Clean_Data!$D$2:$D$501,G22,Clean_Data!$N$2:$N$501,"Delivered")
A23: Retail Store | B23: =SUMIFS(Clean_Data!$O$2:$O$501,Clean_Data!$F$2:$F$501,A23,Clean_Data!$N$2:$N$501,"Delivered") | G23: West | H23: =SUMIFS(Clean_Data!$O$2:$O$501,Clean_Data!$D$2:$D$501,G23,Clean_Data!$N$2:$N$501,"Delivered")
A24: Social Media | B24: =SUMIFS(Clean_Data!$O$2:$O$501,Clean_Data!$F$2:$F$501,A24,Clean_Data!$N$2:$N$501,"Delivered") | G24: Central | H24: =SUMIFS(Clean_Data!$O$2:$O$501,Clean_Data!$D$2:$D$501,G24,Clean_Data!$N$2:$N$501,"Delivered")

Sheet Data_Dictionary
A1: Column | B1: Description | C1: Format
A2: Order_ID | B2: Unique synthetic order identifier | C2: Text
A3: Order_Date | B3: Date on which order was placed | C3: YYYY-MM-DD
A4: Customer_ID | B4: Synthetic customer identifier | C4: Text
A5: Region | B5: Sales region | C5: Category
A6: City | B6: Customer/order city | C6: City
A7: Sales_Channel | B7: Channel through which order was placed | C7: Category
A8: Category | B8: Product category | C8: Category
A9: Product | B9: Product name | C9: Text
A10: Quantity | B10: Units ordered | C10: Integer
A11: Unit_Price_INR | B11: Price per unit before discount | C11: INR
A12: Discount_Rate | B12: Discount as decimal fraction | C12: 0–0.15
... A19: Order_Outcome | B19: Simplified mapped order outcome | C19: Category

Sheet Start_Here
A1: PROJECT GUIDE | E-COMMERCE ANALYTICS
A4: Objective | B4: Analyze synthetic e-commerce orders to compare delivered revenue, estimated profit, category performance, region and channel.
A5: Dashboard | B5: Change Dashboard!B4 to All or a region to update KPI cards.
A6: Raw_Data | B6: Original synthetic order records preserved.
A7: Clean_Data | B7: Missing channels labeled Not specified; text fields trimmed; revenue, estimated profit and month columns added.
A8: Analysis | B8: Formula-driven monthly, category, sales-channel, order-status and region summaries.
A9: Revenue definition | B9: Revenue = quantity × unit price × (1 − discount); KPI revenue includes Delivered orders only.
A10: Important | B10: Synthetic educational data; not real customer/order data. Profit uses estimated costs and is not audited accounting profit.
